package retry

import (
	"context"
	"errors"
	"fmt"
	"testing"
	"time"

	"github.com/sirupsen/logrus"
	"github.com/sirupsen/logrus/hooks/test"
	"github.com/stretchr/testify/assert"
	"github.com/stretchr/testify/require"

	"github.com/Scalingo/go-utils/logger"
)

func TestRetrier(t *testing.T) {
	t.Run("When the method works fine the first time", func(t *testing.T) {
		retrier := New()
		tries := 0
		err := retrier.Do(context.Background(), func(ctx context.Context) error {
			tries++
			return nil
		})

		assert.NoError(t, err)
		assert.Equal(t, tries, 1)
	})

	t.Run("When the method works fine the second time", func(t *testing.T) {
		retrier := New(WithWaitDuration(100 * time.Millisecond))
		tries := 0
		before := time.Now()
		err := retrier.Do(context.Background(), func(ctx context.Context) error {
			tries++
			if tries == 2 {
				return nil
			}
			return fmt.Errorf("Error attempt %v", tries)
		})
		duration := time.Since(before)

		assert.NoError(t, err)
		assert.Equal(t, tries, 2)
		if duration < 100*time.Millisecond {
			t.Fatalf("Test should take at least 100ms, took %v", duration)
		}
	})

	t.Run("When the method never returns", func(t *testing.T) {
		retrier := New(WithWaitDuration(1 * time.Millisecond))
		err := retrier.Do(context.Background(), func(ctx context.Context) error {
			return errors.New("nop")
		})

		require.Error(t, err)
	})

	t.Run("It should cancel the retry if a RetryCancelError is retuned", func(t *testing.T) {
		retrier := New(WithWaitDuration(1 * time.Millisecond))
		count := 0
		err := retrier.Do(context.Background(), func(ctx context.Context) error {
			count++
			return NewRetryCancelError(errors.New("nop"))
		})

		require.Error(t, err)
		assert.Equal(t, count, 1)
	})

	t.Run("When the context is canceled after the first try", func(t *testing.T) {
		retrier := New(WithWaitDuration(1 * time.Millisecond))
		tries := 0
		ctx, cancel := context.WithCancel(context.Background())
		err := retrier.Do(ctx, func(ctx context.Context) error {
			tries++
			if tries == 2 {
				return nil
			}
			cancel()
			return fmt.Errorf("Error attempt %v", tries)
		})

		require.Error(t, err)
		assert.Equal(t, tries, 1)
	})

	t.Run("With timeout should ignore sleep", func(t *testing.T) {
		retrier := New(WithWaitDuration(1 * time.Second))
		ctx, cancel := context.WithTimeout(context.Background(), 50*time.Millisecond)
		defer cancel()

		before := time.Now()
		err := retrier.Do(ctx, func(ctx context.Context) error {
			return errors.New("retry test error")
		})

		require.Error(t, err)
		assert.WithinDuration(t, time.Now(), before, 100*time.Millisecond)
		require.IsType(t, RetryError{}, err)
		assert.EqualValues(t, err.(RetryError).Scope, ContextScope)
		assert.Equal(t, err.(RetryError).Err, context.DeadlineExceeded)
		assert.Equal(t, err.(RetryError).LastErr.Error(), "retry test error")
	})

	t.Run("With max duration it should ignore sleep", func(t *testing.T) {
		retrier := New(
			WithWaitDuration(1*time.Second),
			WithMaxDuration(50*time.Millisecond),
		)

		before := time.Now()
		err := retrier.Do(context.Background(), func(ctx context.Context) error {
			return errors.New("max duration error")
		})

		require.Error(t, err)
		assert.WithinDuration(t, time.Now(), before, 100*time.Millisecond)
		require.IsType(t, RetryError{}, err)
		assert.EqualValues(t, err.(RetryError).Scope, MaxDurationScope)
		assert.Equal(t, err.(RetryError).Err, context.DeadlineExceeded)
		assert.Equal(t, err.(RetryError).LastErr.Error(), "max duration error")
	})

	t.Run("With a callback", func(t *testing.T) {
		callbackCalls := 0
		retrier := New(
			WithMaxAttempts(1),
			WithWaitDuration(50*time.Millisecond),
			WithWaitDuration(100*time.Millisecond),
			WithErrorCallback(func(ctx context.Context, err error, currentAttempt, maxAttempts int) {
				callbackCalls++
				assert.Equal(t, err.Error(), "TestError")
				assert.Equal(t, 0, currentAttempt)
				assert.Equal(t, 1, maxAttempts)
			}),
		)

		err := retrier.Do(context.Background(), func(ctx context.Context) error {
			return errors.New("TestError")
		})
		require.Error(t, err)
		assert.Equal(t, callbackCalls, 1)
	})

	t.Run("If both timeout are specified, the first one which is expired should exist the method", func(t *testing.T) {
		// Timeout from call context first
		retrier := New(
			WithWaitDuration(1*time.Second),
			WithMaxDuration(500*time.Millisecond),
		)

		ctx, cancel := context.WithTimeout(context.Background(), 50*time.Millisecond)
		defer cancel()

		before := time.Now()
		err := retrier.Do(ctx, func(ctx context.Context) error {
			return errors.New("test")
		})

		require.Error(t, err)
		assert.WithinDuration(t, time.Now(), before, 100*time.Millisecond)
		require.IsType(t, RetryError{}, err)
		assert.EqualValues(t, err.(RetryError).Scope, ContextScope)
		assert.Equal(t, err.(RetryError).Err, context.DeadlineExceeded)

		// Timeout from MaxDuration first
		retrier = New(
			WithWaitDuration(1*time.Second),
			WithMaxDuration(50*time.Millisecond),
		)

		ctx, cancel = context.WithTimeout(context.Background(), 500*time.Millisecond)
		defer cancel()

		before = time.Now()
		err = retrier.Do(ctx, func(ctx context.Context) error {
			return errors.New("test")
		})

		require.Error(t, err)
		assert.WithinDuration(t, time.Now(), before, 100*time.Millisecond)
		require.IsType(t, RetryError{}, err)
		assert.EqualValues(t, err.(RetryError).Scope, MaxDurationScope)
		assert.Equal(t, err.(RetryError).Err, context.DeadlineExceeded)
	})

	t.Run("If logging on attempt error is set, it should log the error", func(t *testing.T) {
		log, hook := test.NewNullLogger()
		ctx := logger.ToCtx(t.Context(), log)

		retrier := New(
			WithMaxAttempts(2),
			WithWaitDuration(10*time.Millisecond),
			WithLoggingOnAttemptError(logrus.ErrorLevel),
		)

		err := retrier.Do(ctx, func(_ context.Context) error {
			return errors.New("TestError")
		})
		require.Error(t, err)

		assert.Len(t, hook.Entries, 2)
		assert.Contains(t, "attempt failed", hook.Entries[0].Message)
		assert.Equal(t, logrus.ErrorLevel, hook.Entries[0].Level)
	})
}
